<?xml version="1.0"?>
<robot xmlns:xacro="http://www.ros.org/wiki/xacro">

    <xacro:include filename="inertial_macros.xacro"/>

    <material name="white">
        <color rgba="1 1 1 1" />
    </material>
    
    <material name="orange">
        <color rgba="1 0.3 0.1 1" />
    </material>
    
    <material name="blue">
        <color rgba="0.2 0.2 1 1" />
    </material>
    
    <material name="black">
        <color rgba="0 0 0 1" />
    </material>

    <material name="red">
        <color rgba="1 0 0 1" />
    </material>

<!-- BASE LINK -->

    <link name="base_link">

    </link>

<!-- CHASSIS  LINK-->

    <joint name="chassis_joint" type="fixed">
        <parent link="base_link" />
        <child link="chassis"/>
        <origin xyz="0 0 0"/>
    </joint>

    <link name="chassis">
        <visual>
            <origin xyz="0 0 0.08"/>
            <geometry>
                <box size="0.4 0.25 0.16"/>
            </geometry>
            <material name="white"/>
        </visual>
        <collision>
            <origin xyz="0 0 0.08"/>
            <geometry>
                <box size="0.4 0.25 0.16"/>
            </geometry>
        </collision>
        <xacro:inertial_box mass="0.5" x="0.4" y="0.25" z="0.16">
            <origin xyz="0 0 0.08" rpy="0 0 0"/>
        </xacro:inertial_box>
    </link>

    <gazebo reference="chassis">
        <material>Gazebo/White</material>
    </gazebo>

<!-- LEFT FRONT WHEEL -->

<!--  <joint name="left_front_wheel_joint" type="continuous">
        <parent link="base_link"/>
        <child link="left_front_wheel"/>
        <origin  xyz="0.165 0.14 -0.08" rpy="1.5708 0 0"/>
        <axis xyz="0 0 1"/>
    </joint>

    <link name="left_front_wheel">
        <visual>
            <geometry>
                <cylinder radius="0.03" length="0.03"/>
            </geometry>
            <material name="blue"/>    
        </visual>
-->

<link name="wheel_front_left_link">
  <visual>
    <geometry>
      <cylinder radius="0.03" length="0.03"/>
    </geometry>
    <origin xyz="0 0 0" rpy="0 0 0"/> <!-- agar menghadap ke samping -->
    <material name="black">
      <color rgba="0 0 0 1"/>
    </material>
  </visual>
  <collision>
    <geometry>
      <cylinder radius="0.03" length="0.03"/>
      <origin xyz="0 0 0" rpy="0 0 0"/>
    </geometry>
  </collision>
  <!-- <xacro:inertial_cylinder mass="0.1" length="0.04" radius="0.05"> -->
  <xacro:inertial_cylinder mass="0.1" length="0.03" radius="0.03">
    <origin xyz="0 0 0" rpy="0 0 0"/>
  </xacro:inertial_cylinder>
</link>
<gazebo reference="wheel_front_left_link">
    <material>Gazebo/Blue</material>
</gazebo>
<joint name="base_to_wheel_front_left" type="continuous">
  <parent link="base_link"/>
  <child link="wheel_front_left_link"/>
  <origin xyz="0.165 0.14 0" rpy="${pi/2} 0 0"/>
  <axis xyz="0 0 -1"/>
</joint>

<!-- kanan-depan -->
<link name="wheel_front_right_link">
  <visual>
    <geometry>
      <cylinder radius="0.03" length="0.03"/>
    </geometry>
    <origin xyz="0 0 0" rpy="0 0 0"/>
    <material name="black">
      <color rgba="0 0 0 1"/>
    </material>
  </visual>
  <collision>
    <geometry>
      <cylinder radius="0.03" length="0.03"/>
      <origin xyz="0 0 0" rpy="0 0 0"/>
    </geometry>
  </collision>
  <xacro:inertial_cylinder mass="0.1" length="0.03" radius="0.03">
    <origin xyz="0 0 0" rpy="0 0 0"/>
  </xacro:inertial_cylinder>
</link>
<gazebo reference="wheel_front_right_link">
    <material>Gazebo/Blue</material>
</gazebo>
<joint name="base_to_wheel_front_right" type="continuous">
  <parent link="base_link"/>
  <child link="wheel_front_right_link"/>
  <origin xyz="0.165 -0.14 0" rpy="${pi/2} 0 0"/>
  <axis xyz="0 0 -1"/>
</joint>

<!-- kiri-belakang -->
<link name="wheel_back_left_link">
  <visual>
    <geometry>
      <cylinder radius="0.03" length="0.03"/>
    </geometry>
    <origin xyz="0 0 0" rpy="0 0 0"/>
    <material name="black">
      <color rgba="0 0 0 1"/>
    </material>
  </visual>
  <collision>
    <geometry>
      <cylinder radius="0.03" length="0.03"/>
      <origin xyz="0 0 0" rpy="0 0 0"/>
    </geometry>
  </collision>
  <xacro:inertial_cylinder mass="0.1" length="0.03" radius="0.03">
    <origin xyz="0 0 0" rpy="0 0 0"/>
  </xacro:inertial_cylinder>
</link>
<gazebo reference="wheel_back_left_link">
    <material>Gazebo/Blue</material>
</gazebo>
<joint name="base_to_wheel_back_left" type="continuous">
  <parent link="base_link"/>
  <child link="wheel_back_left_link"/>
  <origin xyz="-0.165 0.14 0" rpy="${pi/2} 0 0"/>
  <axis xyz="0 0 -1"/>
</joint>

<!-- kanan-belakang -->
<link name="wheel_back_right_link">
  <visual>
    <geometry>
      <cylinder radius="0.03" length="0.03"/>
    </geometry>
    <origin xyz="0 0 0" rpy="0 0 0"/>
    <material name="black">
      <color rgba="0 0 0 1"/>
    </material>
  </visual>
  <collision>
    <geometry>
      <cylinder radius="0.03" length="0.03"/>
      <origin xyz="0 0 0" rpy="0 0 0"/>
    </geometry>
  </collision>
  <xacro:inertial_cylinder mass="0.1" length="0.03" radius="0.03">
    <origin xyz="0 0 0" rpy="0 0 0"/>
  </xacro:inertial_cylinder>
</link>
<gazebo reference="wheel_back_right_link">
    <material>Gazebo/Blue</material>
</gazebo>
<joint name="base_to_wheel_back_right" type="continuous">
  <parent link="base_link"/>
  <child link="wheel_back_right_link"/>
  <origin xyz="-0.165 -0.14 0" rpy="${pi/2} 0 0"/>
  <axis xyz="0 0 -1"/>
</joint>


</robot>